<mujoco model="DOG">
  <compiler angle="radian"/>

  <asset>
    <mesh name="BASE_LINK" file="BASE_LINK.STL"/>
    <mesh name="FL_ABAD_LINK" file="FL_ABAD_LINK.STL"/>
    <mesh name="FL_HIP_LINK" file="FL_HIP_LINK.STL"/>
    <mesh name="FL_KNEE_LINK" file="FL_KNEE_LINK.STL"/>
    <mesh name="FL_FOOT_LINK" file="FL_FOOT_LINK.STL"/>
    <mesh name="FR_ABAD_LINK" file="FR_ABAD_LINK.STL"/>
    <mesh name="FR_HIP_LINK" file="FR_HIP_LINK.STL"/>
    <mesh name="FR_KNEE_LINK" file="FR_KNEE_LINK.STL"/>
    <mesh name="FR_FOOT_LINK" file="FR_FOOT_LINK.STL"/>
    <mesh name="RR_ABAD_LINK" file="RR_ABAD_LINK.STL"/>
    <mesh name="RR_HIP_LINK" file="RR_HIP_LINK.STL"/>
    <mesh name="RR_KNEE_LINK" file="RR_KNEE_LINK.STL"/>
    <mesh name="RR_FOOT_LINK" file="RR_FOOT_LINK.STL"/>
    <mesh name="RL_ABAD_LINK" file="RL_ABAD_LINK.STL"/>
    <mesh name="RL_HIP_LINK" file="RL_HIP_LINK.STL"/>
    <mesh name="RL_KNEE_LINK" file="RL_KNEE_LINK.STL"/>
    <mesh name="RL_FOOT_LINK" file="RL_FOOT_LINK.STL"/>
  </asset>

  <worldbody>
    <!-- <geom type="mesh" rgba="0.75294 0.75294 0.75294 1" mesh="BASE_LINK"/> -->
    <body name="BASE_LINK" pos="0 0 0.35">
      <inertial pos="0.0054244583 -0.00036330247 0.0060908623" quat="0.0111438 0.707126 -0.00935374 0.706938" mass="6.268375" diaginertia="0.027359128 0.084984679 0.099223551" />
      <joint type="free" />
      <geom type="mesh" contype="0" conaffinity="0" group="1" rgba="0.75294 0.75294 0.75294 1" mesh="BASE_LINK" />
      <body name="FL_hip" pos="0.17449 0.062 0">
        <inertial pos="-0.0270745 -0.0154588 9.41679e-06" quat="0.600186 0.60017 0.373963 0.373798" mass="0.454098" diaginertia="0.000562658 0.000541021 0.00017585"/>
        <joint name="FL_hip_joint" pos="0 0 0" axis="1 0 0" range="-0.4887 0.4887" actuatorfrcrange="-28 28"/>
        <geom type="mesh" rgba="0.75294 0.75294 0.75294 1" mesh="FL_ABAD_LINK"/>
        <body name="FL_thigh" pos="0 0.097412 0">
          <inertial pos="-0.00334388 -0.042909 -0.0216077" quat="0.961876 0.267908 0.0543528 0.00804932" mass="1.50165" diaginertia="0.00700226 0.00563861 0.0023263"/>
          <joint name="FL_thigh_joint" pos="0 0 0" axis="0 1 0" range="-1.1519 2.967" actuatorfrcrange="-28 28"/>
          <geom type="mesh" rgba="0.75294 0.75294 0.75294 1" mesh="FL_HIP_LINK"/>
          <body name="FL_calf" pos="0 0 -0.2">
            <inertial pos="-0.0394618 -4.07678e-05 -0.0493743" quat="0.672025 -0.218998 -0.219188 0.672591" mass="0.270529" diaginertia="0.00521349 0.00452384 0.000728981"/>
            <joint name="FL_calf_joint" pos="0 0 0" axis="0 1 0" range="-2.723 -0.602" actuatorfrcrange="-28 28"/>
            <geom type="mesh" rgba="0.49804 0.49804 0.49804 1" mesh="FL_KNEE_LINK"/>
            <geom pos="0 0 -0.21366" quat="1 0 0 0" type="mesh" rgba="0.75294 0.75294 0.75294 1" mesh="FL_FOOT_LINK"/>
          </body>
        </body>
      </body>
      <body name="FR_hip" pos="0.17449 -0.062 0">
        <inertial pos="-0.0270745 0.0154588 -9.41679e-06" quat="0.373963 0.373798 0.600186 0.60017" mass="0.454098" diaginertia="0.000562658 0.000541021 0.00017585"/>
        <joint name="FR_hip_joint" pos="0 0 0" axis="1 0 0" range="-0.4887 0.4887" actuatorfrcrange="-28 28"/>
        <geom type="mesh" rgba="0.75294 0.75294 0.75294 1" mesh="FR_ABAD_LINK"/>
        <body name="FR_thigh" pos="0 -0.097399 0">
          <inertial pos="-0.00342445 0.0427303 -0.0223257" quat="0.964115 -0.259871 0.0534872 -0.00934672" mass="1.50799" diaginertia="0.00720259 0.00582228 0.00234676"/>
          <joint name="FR_thigh_joint" pos="0 0 0" axis="0 1 0" range="-1.1519 2.967" actuatorfrcrange="-28 28"/>
          <geom type="mesh" rgba="0.75294 0.75294 0.75294 1" mesh="FR_HIP_LINK"/>
          <body name="FR_calf" pos="0 0 -0.2">
            <inertial pos="-0.0394618 -4.07678e-05 -0.0493743" quat="0.672025 -0.218998 -0.219188 0.672591" mass="0.270529" diaginertia="0.00521349 0.00452384 0.000728981"/>
            <joint name="FR_calf_joint" pos="0 0 0" axis="0 1 0" range="-2.723 -0.602" actuatorfrcrange="-28 28"/>
            <geom type="mesh" rgba="0.49804 0.49804 0.49804 1" mesh="FR_KNEE_LINK"/>
            <geom pos="0 0 -0.21366" quat="1 0 0 0" type="mesh" rgba="0.75294 0.75294 0.75294 1" mesh="FR_FOOT_LINK"/>
          </body>
        </body>
      </body>
      <body name="RR_hip" pos="-0.17449 -0.062 0">
        <inertial pos="0.0270745 0.0154588 9.41679e-06" quat="0.60017 0.600186 0.373798 0.373963" mass="0.454098" diaginertia="0.000562658 0.000541021 0.00017585"/>
        <joint name="RR_hip_joint" pos="0 0 0" axis="1 0 0" range="-0.4887 0.4887" actuatorfrcrange="-28 28"/>
        <geom type="mesh" rgba="0.75294 0.75294 0.75294 1" mesh="RR_ABAD_LINK"/>
        <body name="RR_thigh" pos="0 -0.0974 0">
          <inertial pos="-0.00342445 0.0427303 -0.0223257" quat="0.964115 -0.259871 0.0534872 -0.00934672" mass="1.50799" diaginertia="0.00720259 0.00582228 0.00234676"/>
          <joint name="RR_thigh_joint" pos="0 0 0" axis="0 1 0" range="-1.1519 2.967" actuatorfrcrange="-28 28"/>
          <geom type="mesh" rgba="0.75294 0.75294 0.75294 1" mesh="RR_HIP_LINK"/>
          <body name="RR_calf" pos="0 0 -0.2">
            <inertial pos="-0.0394618 -4.07678e-05 -0.0493743" quat="0.672025 -0.218998 -0.219188 0.672591" mass="0.270529" diaginertia="0.00521349 0.00452384 0.000728981"/>
            <joint name="RR_calf_joint" pos="0 0 0" axis="0 1 0" range="-2.723 -0.602" actuatorfrcrange="-28 28"/>
            <geom type="mesh" rgba="0.49804 0.49804 0.49804 1" mesh="RR_KNEE_LINK"/>
            <geom pos="0 0 -0.21366" quat="1 0 0 0" type="mesh" rgba="0.75294 0.75294 0.75294 1" mesh="RR_FOOT_LINK"/>
          </body>
        </body>
      </body>
      <body name="RL_hip" pos="-0.17449 0.062 0">
        <inertial pos="0.0270745 -0.0154588 -9.41679e-06" quat="0.373798 0.373963 0.60017 0.600186" mass="0.454098" diaginertia="0.000562658 0.000541021 0.00017585"/>
        <joint name="RL_hip_joint" pos="0 0 0" axis="1 0 0" range="-0.4887 0.4887" actuatorfrcrange="-28 28"/>
        <geom type="mesh" rgba="0.75294 0.75294 0.75294 1" mesh="RL_ABAD_LINK"/>
        <body name="RL_thigh" pos="0 0.097412 0">
          <inertial pos="-0.00334388 -0.042909 -0.0216077" quat="0.961876 0.267908 0.0543528 0.00804932" mass="1.50165" diaginertia="0.00700226 0.00563861 0.0023263"/>
          <joint name="RL_thigh_joint" pos="0 0 0" axis="0 1 0" range="-1.1519 2.967" actuatorfrcrange="-28 28"/>
          <geom type="mesh" rgba="0.75294 0.75294 0.75294 1" mesh="RL_HIP_LINK"/>
          <body name="RL_calf" pos="0 0 -0.2">
            <inertial pos="-0.0394618 -4.07678e-05 -0.0493743" quat="0.672025 -0.218998 -0.219188 0.672591" mass="0.270529" diaginertia="0.00521349 0.00452384 0.000728981"/>
            <joint name="RL_calf_joint" pos="0 0 0" axis="0 1 0" range="-2.723 -0.602" actuatorfrcrange="-28 28"/>
            <geom type="mesh" rgba="0.49804 0.49804 0.49804 1" mesh="RL_KNEE_LINK"/>
            <geom pos="0 0 -0.21366" quat="1 0 0 0" type="mesh" rgba="0.75294 0.75294 0.75294 1" mesh="RL_FOOT_LINK"/>
          </body>
        </body>
      </body>
    </body>
  </worldbody>
  <actuator>
    <motor name="FL_hip"   joint="FL_hip_joint"/>
    <motor name="FL_thigh" joint="FL_thigh_joint"/>
    <motor name="FL_calf"  joint="FL_calf_joint"/>
    <motor name="FR_hip"   joint="FR_hip_joint"/>
    <motor name="FR_thigh" joint="FR_thigh_joint"/>
    <motor name="FR_calf"  joint="FR_calf_joint"/>
    <motor name="RR_hip"   joint="RR_hip_joint"/>
    <motor name="RR_thigh" joint="RR_thigh_joint"/>
    <motor name="RR_calf"  joint="RR_calf_joint"/>
    <motor name="RL_hip"   joint="RL_hip_joint"/>
    <motor name="RL_thigh" joint="RL_thigh_joint"/>
    <motor name="RL_calf"  joint="RL_calf_joint"/>
  </actuator>
</mujoco>
